
GeForce RTX 2060 Super Mini

### nvidia-driver-440

## tensorflow:1.14.0-gpu-py3

2019-11-08 20:59:04.434734: I tensorflow/stream_executor/platform/default/dso_loader.cc:42] Successfully opened dynamic library libcublas.so.10.0
2019-11-08 20:59:04.637124: I tensorflow/stream_executor/platform/default/dso_loader.cc:42] Successfully opened dynamic library libcudnn.so.7
2019-11-08 20:59:05.800892: E tensorflow/stream_executor/cuda/cuda_dnn.cc:329] Could not create cudnn handle: CUDNN_STATUS_INTERNAL_ERROR
2019-11-08 20:59:05.808630: E tensorflow/stream_executor/cuda/cuda_dnn.cc:329] Could not create cudnn handle: CUDNN_STATUS_INTERNAL_ERROR
Traceback (most recent call last):
  File "<stdin>", line 6, in <module>
  File "/usr/local/lib/python3.6/dist-packages/tensorflow/python/keras/engine/training.py", line 1433, in fit_generator
    steps_name='steps_per_epoch')
  File "/usr/local/lib/python3.6/dist-packages/tensorflow/python/keras/engine/training_generator.py", line 264, in model_iteration
    batch_outs = batch_function(*batch_data)
  File "/usr/local/lib/python3.6/dist-packages/tensorflow/python/keras/engine/training.py", line 1175, in train_on_batch
    outputs = self.train_function(ins)  # pylint: disable=not-callable
  File "/usr/local/lib/python3.6/dist-packages/tensorflow/python/keras/backend.py", line 3292, in __call__
    run_metadata=self.run_metadata)
  File "/usr/local/lib/python3.6/dist-packages/tensorflow/python/client/session.py", line 1458, in __call__
    run_metadata_ptr)
tensorflow.python.framework.errors_impl.UnknownError: 2 root error(s) found.
  (0) Unknown: Failed to get convolution algorithm. This is probably because cuDNN failed to initialize, so try looking to see if a warning log message was printed above.
	 [[{{node conv1/Conv2D}}]]
	 [[metrics/acc/Identity/_895]]
  (1) Unknown: Failed to get convolution algorithm. This is probably because cuDNN failed to initialize, so try looking to see if a warning log message was printed above.
	 [[{{node conv1/Conv2D}}]]
0 successful operations.
0 derived errors ignored.
>>>     # epochs = 30)
...     # epochs = 100)



## tensorflow:latest-gpu-py3

2019-11-08 21:20:12.038406: I tensorflow/stream_executor/platform/default/dso_loader.cc:44] Successfully opened dynamic library libcudnn.so.7
2019-11-08 21:20:12.407474: E tensorflow/stream_executor/cuda/cuda_dnn.cc:329] Could not create cudnn handle: CUDNN_STATUS_INTERNAL_ERROR
2019-11-08 21:20:12.429194: E tensorflow/stream_executor/cuda/cuda_dnn.cc:329] Could not create cudnn handle: CUDNN_STATUS_INTERNAL_ERROR
Traceback (most recent call last):
  File "<stdin>", line 6, in <module>
  File "/usr/local/lib/python3.6/dist-packages/tensorflow_core/python/keras/engine/training.py", line 1297, in fit_generator
    steps_name='steps_per_epoch')
  File "/usr/local/lib/python3.6/dist-packages/tensorflow_core/python/keras/engine/training_generator.py", line 265, in model_iteration
    batch_outs = batch_function(*batch_data)
  File "/usr/local/lib/python3.6/dist-packages/tensorflow_core/python/keras/engine/training.py", line 973, in train_on_batch
    class_weight=class_weight, reset_metrics=reset_metrics)
  File "/usr/local/lib/python3.6/dist-packages/tensorflow_core/python/keras/engine/training_v2_utils.py", line 264, in train_on_batch
    output_loss_metrics=model._output_loss_metrics)
  File "/usr/local/lib/python3.6/dist-packages/tensorflow_core/python/keras/engine/training_eager.py", line 311, in train_on_batch
    output_loss_metrics=output_loss_metrics))
  File "/usr/local/lib/python3.6/dist-packages/tensorflow_core/python/keras/engine/training_eager.py", line 252, in _process_single_batch
    training=training))
  File "/usr/local/lib/python3.6/dist-packages/tensorflow_core/python/keras/engine/training_eager.py", line 127, in _model_loss
    outs = model(inputs, **kwargs)
  File "/usr/local/lib/python3.6/dist-packages/tensorflow_core/python/keras/engine/base_layer.py", line 891, in __call__
    outputs = self.call(cast_inputs, *args, **kwargs)
  File "/usr/local/lib/python3.6/dist-packages/tensorflow_core/python/keras/engine/network.py", line 708, in call
    convert_kwargs_to_constants=base_layer_utils.call_context().saving)
  File "/usr/local/lib/python3.6/dist-packages/tensorflow_core/python/keras/engine/network.py", line 860, in _run_internal_graph
    output_tensors = layer(computed_tensors, **kwargs)
  File "/usr/local/lib/python3.6/dist-packages/tensorflow_core/python/keras/engine/base_layer.py", line 891, in __call__
    outputs = self.call(cast_inputs, *args, **kwargs)
  File "/usr/local/lib/python3.6/dist-packages/tensorflow_core/python/keras/layers/convolutional.py", line 197, in call
    outputs = self._convolution_op(inputs, self.kernel)
  File "/usr/local/lib/python3.6/dist-packages/tensorflow_core/python/ops/nn_ops.py", line 1134, in __call__
    return self.conv_op(inp, filter)
  File "/usr/local/lib/python3.6/dist-packages/tensorflow_core/python/ops/nn_ops.py", line 639, in __call__
    return self.call(inp, filter)
  File "/usr/local/lib/python3.6/dist-packages/tensorflow_core/python/ops/nn_ops.py", line 238, in __call__
    name=self.name)
  File "/usr/local/lib/python3.6/dist-packages/tensorflow_core/python/ops/nn_ops.py", line 2010, in conv2d
    name=name)
  File "/usr/local/lib/python3.6/dist-packages/tensorflow_core/python/ops/gen_nn_ops.py", line 1031, in conv2d
    data_format=data_format, dilations=dilations, name=name, ctx=_ctx)
  File "/usr/local/lib/python3.6/dist-packages/tensorflow_core/python/ops/gen_nn_ops.py", line 1130, in conv2d_eager_fallback
    ctx=_ctx, name=name)
  File "/usr/local/lib/python3.6/dist-packages/tensorflow_core/python/eager/execute.py", line 67, in quick_execute
    six.raise_from(core._status_to_exception(e.code, message), None)
  File "<string>", line 3, in raise_from
tensorflow.python.framework.errors_impl.UnknownError: Failed to get convolution algorithm. This is probably because cuDNN failed to initialize, so try looking to see if a warning log message was printed above. [Op:Conv2D]
>>>     # epochs = 30)
...     # epochs = 100)
